<robot name="robot">
  
  <link name="base_link" />
<link name="link_1">
    <inertial>
      <origin xyz="1.72427e-05 -6.16494e-06 0.0796307" rpy="0 0 0" />
      <mass value="0.76382" />
      <inertia ixx="0.00155344" ixy="-7.08057e-08" ixz="8.71472e-07" iyy="0.0015524" iyz="7.81479e-07" izz="0.00111147" />
    </inertial>
    
    <visual>
      <origin xyz="1.72427e-05 -6.16494e-06 0.0796307" rpy="0 -0 0" />
      <geometry>
        <mesh filename="package://robot_description/meshes/link_1_visual.stl" />
      </geometry>
      <material name="link_1_parts_material">
        <color rgba="0.5 0.5 0.5 1" />
      </material>
    </visual>
    <collision>
      <origin xyz="1.72427e-05 -6.16494e-06 0.0796307" rpy="0 -0 0" />
      <geometry>
        <mesh filename="package://robot_description/meshes/link_1_collision.stl" />
      </geometry>
    </collision>
  </link>
  
  <link name="world">
    <origin xyz="0 0 0" rpy="0 -0 0" />
    <inertial>
      <origin xyz="0 0 0" rpy="0 0 0" />
      <mass value="1e-9" />
      <inertia ixx="0" ixy="0" ixz="0" iyy="0" iyz="0" izz="0" />
    </inertial>
  </link>
  <joint name="world_frame" type="fixed">
    <origin xyz="-1.42177e-33 -0.35 0" rpy="0 2.10045e-17 5.6569e-32" />
    <parent link="link_1" />
    <child link="world" />
    <axis xyz="0 0 0" />
  </joint>
  
  <link name="link_2">
    <inertial>
      <origin xyz="0.0537175 -8.69412e-08 0.0491974" rpy="0 0 0" />
      <mass value="0.633312" />
      <inertia ixx="0.000846487" ixy="-6.13959e-09" ixz="-0.000284405" iyy="0.00107115" iyz="-4.65024e-09" izz="0.00100826" />
    </inertial>
    
    <visual>
      <origin xyz="0.0537175 -8.69412e-08 0.0491974" rpy="-8.84447e-32 -2.10045e-17 -1.5708" />
      <geometry>
        <mesh filename="package://robot_description/meshes/link_2_visual.stl" />
      </geometry>
      <material name="link_2_parts_material">
        <color rgba="0.5 0.5 0.5 1" />
      </material>
    </visual>
    <collision>
      <origin xyz="0.0537175 -8.69412e-08 0.0491974" rpy="-8.84447e-32 -2.10045e-17 -1.5708" />
      <geometry>
        <mesh filename="package://robot_description/meshes/link_2_collision.stl" />
      </geometry>
    </collision>
  </link>
  
  <link name="link_3">
    <inertial>
      <origin xyz="-0.130027 -1.2201e-07 0.0184573" rpy="0 0 0" />
      <mass value="0.702237" />
      <inertia ixx="0.00101854" ixy="7.1996e-09" ixz="-0.000683603" iyy="0.00525624" iyz="-3.6986e-07" izz="0.00499616" />
    </inertial>
    
    <visual>
      <origin xyz="-0.130027 -1.2201e-07 0.0184573" rpy="1.5708 -1.20074e-14 -1.5708" />
      <geometry>
        <mesh filename="package://robot_description/meshes/link_3_visual.stl" />
      </geometry>
      <material name="link_3_parts_material">
        <color rgba="0.5 0.5 0.5 1" />
      </material>
    </visual>
    <collision>
      <origin xyz="-0.130027 -1.2201e-07 0.0184573" rpy="1.5708 -1.20074e-14 -1.5708" />
      <geometry>
        <mesh filename="package://robot_description/meshes/link_3_collision.stl" />
      </geometry>
    </collision>
  </link>
  
  <link name="link_4">
    <inertial>
      <origin xyz="1.56721e-08 0.0432144 -0.0420553" rpy="0 0 0" />
      <mass value="0.414775" />
      <inertia ixx="0.00051508" ixy="-3.72268e-07" ixz="3.9964e-10" iyy="0.000386" iyz="0.000143525" izz="0.000474474" />
    </inertial>
    
    <visual>
      <origin xyz="1.56721e-08 0.0432144 -0.0420553" rpy="1.5708 -1.2285e-14 -3.14159" />
      <geometry>
        <mesh filename="package://robot_description/meshes/link_4_visual.stl" />
      </geometry>
      <material name="link_4_parts_material">
        <color rgba="0.5 0.5 0.5 1" />
      </material>
    </visual>
    <collision>
      <origin xyz="1.56721e-08 0.0432144 -0.0420553" rpy="1.5708 -1.2285e-14 -3.14159" />
      <geometry>
        <mesh filename="package://robot_description/meshes/link_4_collision.stl" />
      </geometry>
    </collision>
  </link>
  
  <link name="link_5">
    <inertial>
      <origin xyz="-0.00142754 2.82863e-05 0.0689265" rpy="0 0 0" />
      <mass value="0.382901" />
      <inertia ixx="0.000740905" ixy="9.75388e-07" ixz="2.11032e-05" iyy="0.00104132" iyz="8.17069e-07" izz="0.000616511" />
    </inertial>
    
    <visual>
      <origin xyz="-0.00142754 2.82863e-05 0.0689265" rpy="3.18629e-15 4.97939e-15 -1.5708" />
      <geometry>
        <mesh filename="package://robot_description/meshes/link_5_visual.stl" />
      </geometry>
      <material name="link_5_parts_material">
        <color rgba="0.5 0.5 0.5 1" />
      </material>
    </visual>
    <collision>
      <origin xyz="-0.00142754 2.82863e-05 0.0689265" rpy="3.18629e-15 4.97939e-15 -1.5708" />
      <geometry>
        <mesh filename="package://robot_description/meshes/link_5_collision.stl" />
      </geometry>
    </collision>
  </link>
  
  <link name="link_6">
    <inertial>
      <origin xyz="-0.00168121 -3.01195e-05 1.05506e-05" rpy="0 0 0" />
      <mass value="0.180127" />
      <inertia ixx="0.000175076" ixy="2.54386e-08" ixz="-3.49791e-09" iyy="0.00017259" iyz="-4.74944e-08" izz="3.43052e-05" />
    </inertial>
    
    <visual>
      <origin xyz="-0.00168121 -3.01195e-05 1.05506e-05" rpy="1.5708 -4.27508e-15 -1.5708" />
      <geometry>
        <mesh filename="package://robot_description/meshes/link_6_visual.stl" />
      </geometry>
      <material name="link_6_parts_material">
        <color rgba="0.5 0.5 0.5 1" />
      </material>
    </visual>
    <collision>
      <origin xyz="-0.00168121 -3.01195e-05 1.05506e-05" rpy="1.5708 -4.27508e-15 -1.5708" />
      <geometry>
        <mesh filename="package://robot_description/meshes/link_6_collision.stl" />
      </geometry>
    </collision>
  </link>
  
  <link name="link_7">
    <inertial>
      <origin xyz="-0.000526668 0.000468214 0.0270907" rpy="0 0 0" />
      <mass value="0.110548" />
      <inertia ixx="3.21016e-05" ixy="-2.14399e-07" ixz="-5.54728e-07" iyy="3.27143e-05" iyz="-1.00514e-07" izz="3.67777e-05" />
    </inertial>
    
    <visual>
      <origin xyz="-0.000526668 0.000468214 0.0270907" rpy="1.5678e-14 8.07815e-15 -1.5708" />
      <geometry>
        <mesh filename="package://robot_description/meshes/link_7_visual.stl" />
      </geometry>
      <material name="link_7_parts_material">
        <color rgba="0.5 0.5 0.5 1" />
      </material>
    </visual>
    <collision>
      <origin xyz="-0.000526668 0.000468214 0.0270907" rpy="1.5678e-14 8.07815e-15 -1.5708" />
      <geometry>
        <mesh filename="package://robot_description/meshes/link_7_collision.stl" />
      </geometry>
    </collision>
  </link>
  
  <joint name="joint_6" type="revolute">
    <origin xyz="-0.0110489 9.05472e-19 0" rpy="2.7759e-17 -1.5708 0" />
    <parent link="link_6" />
    <child link="link_7" />
    <axis xyz="0 0 1" />
    <limit effort="10" velocity="10" lower="-3.14159" upper="3.14159" />
  </joint>
  
  <joint name="joint_5" type="revolute">
    <origin xyz="-5.56846e-16 -1.02085e-15 0.1125" rpy="-6.40729e-15 1.5708 0" />
    <parent link="link_5" />
    <child link="link_6" />
    <axis xyz="0 0 1" />
    <limit effort="10" velocity="10" lower="-1.5708" upper="1.5708" />
  </joint>
  
  <joint name="joint_4" type="revolute">
    <origin xyz="1.26565e-17 0.076 -0.05" rpy="-1.5708 -1.5708 0" />
    <parent link="link_4" />
    <child link="link_5" />
    <axis xyz="0 0 1" />
    <limit effort="10" velocity="10" lower="-3.14159" upper="3.14159" />
  </joint>
  
  <joint name="joint_3" type="revolute">
    <origin xyz="-0.2 4.2689e-08 -0.0259997" rpy="1.06043e-15 -2.77556e-16 1.5708" />
    <parent link="link_3" />
    <child link="link_4" />
    <axis xyz="0 0 1" />
    <limit effort="10" velocity="10" lower="-3.14159" upper="3.14159" />
  </joint>
  
  <joint name="joint_2" type="revolute">
    <origin xyz="0.0895 2.21034e-16 0.0575" rpy="1.2285e-14 1.5708 0" />
    <parent link="link_2" />
    <child link="link_3" />
    <axis xyz="0 0 1" />
    <limit effort="10" velocity="10" lower="-3.14159" upper="3.14159" />
  </joint>
  
  <joint name="joint_1" type="revolute">
    <origin xyz="-8.56257e-17 6.08362e-17 0.1245" rpy="2.10045e-17 -8.84447e-32 1.5708" />
    <parent link="link_1" />
    <child link="link_2" />
    <axis xyz="0 0 1" />
    <limit effort="10" velocity="10" lower="-3.14159" upper="3.14159" />
  </joint>
  
  <joint name="base_link_to_link_1" type="fixed">
    <origin xyz="0 0 0" rpy="0 -0 0" />
    <parent link="base_link" />
    <child link="link_1" />
    <axis xyz="0 0 1" />
    <limit effort="10" velocity="10" />
  </joint>
  
  <ros2_control name="robot" type="system">
    <hardware>
      <plugin>robot_hardware/RobotSystem</plugin>
    </hardware>
    <joint name="joint_1">
      <command_interface name="position">
        <param name="min">${-2*pi}</param>
        <param name="max">${2*pi}</param>
      </command_interface>
      <command_interface name="velocity">
        <param name="min">-3.15</param>
        <param name="max">3.15</param>
      </command_interface>
      <state_interface name="position">
        <param name="initial_value">0.0</param>
      </state_interface>
      <state_interface name="velocity" />
    </joint>
    <joint name="joint_2">
      <command_interface name="position">
        <param name="min">${-2*pi}</param>
        <param name="max">${2*pi}</param>
      </command_interface>
      <command_interface name="velocity">
        <param name="min">-3.15</param>
        <param name="max">3.15</param>
      </command_interface>
      <state_interface name="position">
        <param name="initial_value">0.0</param>
      </state_interface>
      <state_interface name="velocity" />
    </joint>
    <joint name="joint_3">
      <command_interface name="position">
        <param name="min">${-pi}</param>
        <param name="max">${pi}</param>
      </command_interface>
      <command_interface name="velocity">
        <param name="min">-3.15</param>
        <param name="max">3.15</param>
      </command_interface>
      <state_interface name="position">
        <param name="initial_value">0.0</param>
      </state_interface>
      <state_interface name="velocity" />
    </joint>
    <joint name="joint_4">
      <command_interface name="position">
        <param name="min">${-2*pi}</param>
        <param name="max">${2*pi}</param>
      </command_interface>
      <command_interface name="velocity">
        <param name="min">-3.2</param>
        <param name="max">3.2</param>
      </command_interface>
      <state_interface name="position">
        <param name="initial_value">0.0</param>
      </state_interface>
      <state_interface name="velocity" />
    </joint>
    <joint name="joint_5">
      <command_interface name="position">
        <param name="min">${-2*pi}</param>
        <param name="max">${2*pi}</param>
      </command_interface>
      <command_interface name="velocity">
        <param name="min">-3.2</param>
        <param name="max">3.2</param>
      </command_interface>
      <state_interface name="position">
        <param name="initial_value">0.0</param>
      </state_interface>
      <state_interface name="velocity" />
    </joint>
    <joint name="joint_6">
      <command_interface name="position">
        <param name="min">${-2*pi}</param>
        <param name="max">${2*pi}</param>
      </command_interface>
      <command_interface name="velocity">
        <param name="min">-3.2</param>
        <param name="max">3.2</param>
      </command_interface>
      <state_interface name="position">
        <param name="initial_value">0.0</param>
      </state_interface>
      <state_interface name="velocity" />
    </joint>
    <sensor name="tcp_fts_sensor">
      <state_interface name="force.x" />
      <state_interface name="force.y" />
      <state_interface name="force.z" />
      <state_interface name="torque.x" />
      <state_interface name="torque.y" />
      <state_interface name="torque.z" />
    </sensor>
  </ros2_control>
</robot>