<robot name="robot">
  
  <link name="base_link" />
<link name="link_1">
    <inertial>
      <origin xyz="0.000112597 -1.7315e-06 0.0689648" rpy="0 0 0" />
      <mass value="0.552681" />
      <inertia ixx="0.00121492" ixy="-2.42695e-08" ixz="4.10867e-06" iyy="0.00121183" iyz="1.73547e-07" izz="0.000938559" />
    </inertial>
    
    <visual>
      <origin xyz="0.000112597 -1.7315e-06 0.0689648" rpy="0 -0 0" />
      <geometry>
        <mesh filename="package://robot_description/meshes/link_1_visual.stl" />
      </geometry>
      <material name="link_1_parts_material">
        <color rgba="0.5 0.5 0.5 1" />
      </material>
    </visual>
    <collision>
      <origin xyz="0.000112597 -1.7315e-06 0.0689648" rpy="0 -0 0" />
      <geometry>
        <mesh filename="package://robot_description/meshes/link_1_collision.stl" />
      </geometry>
    </collision>
  </link>
  
  <link name="world">
    <origin xyz="0 0 0" rpy="0 -0 0" />
    <inertial>
      <origin xyz="0 0 0" rpy="0 0 0" />
      <mass value="1e-9" />
      <inertia ixx="0" ixy="0" ixz="0" iyy="0" iyz="0" izz="0" />
    </inertial>
  </link>
  <joint name="world_frame" type="fixed">
    <origin xyz="0 -0.35 0" rpy="0 -0 0" />
    <parent link="link_1" />
    <child link="world" />
    <axis xyz="0 0 0" />
  </joint>
  
  <link name="link_2">
    <inertial>
      <origin xyz="5.19217e-07 -0.0441353 0.045004" rpy="0 0 0" />
      <mass value="0.423847" />
      <inertia ixx="0.000832826" ixy="-6.25229e-08" ixz="1.90465e-08" iyy="0.000655255" iyz="0.000233014" izz="0.000790533" />
    </inertial>
    
    <visual>
      <origin xyz="5.19217e-07 -0.0441353 0.045004" rpy="0 -0 3.14159" />
      <geometry>
        <mesh filename="package://robot_description/meshes/link_2_visual.stl" />
      </geometry>
      <material name="link_2_parts_material">
        <color rgba="0.5 0.5 0.5 1" />
      </material>
    </visual>
    <collision>
      <origin xyz="5.19217e-07 -0.0441353 0.045004" rpy="0 -0 3.14159" />
      <geometry>
        <mesh filename="package://robot_description/meshes/link_2_collision.stl" />
      </geometry>
    </collision>
  </link>
  
  <link name="link_3">
    <inertial>
      <origin xyz="2.83887e-07 0.114339 0.0248822" rpy="0 0 0" />
      <mass value="0.573947" />
      <inertia ixx="0.00431729" ixy="3.669e-08" ixz="-3.29061e-08" iyy="0.000851068" iyz="0.000366937" izz="0.00416197" />
    </inertial>
    
    <visual>
      <origin xyz="2.83887e-07 0.114339 0.0248822" rpy="1.5708 2.25307e-15 3.14159" />
      <geometry>
        <mesh filename="package://robot_description/meshes/link_3_visual.stl" />
      </geometry>
      <material name="link_3_parts_material">
        <color rgba="0.5 0.5 0.5 1" />
      </material>
    </visual>
    <collision>
      <origin xyz="2.83887e-07 0.114339 0.0248822" rpy="1.5708 2.25307e-15 3.14159" />
      <geometry>
        <mesh filename="package://robot_description/meshes/link_3_collision.stl" />
      </geometry>
    </collision>
  </link>
  
  <link name="link_4">
    <inertial>
      <origin xyz="1.65309e-07 0.0356415 -0.0384232" rpy="0 0 0" />
      <mass value="0.28613" />
      <inertia ixx="0.000410597" ixy="4.05515e-08" ixz="9.63406e-09" iyy="0.000312287" iyz="0.000117771" izz="0.000381171" />
    </inertial>
    
    <visual>
      <origin xyz="1.65309e-07 0.0356415 -0.0384232" rpy="1.5708 -2.40282e-15 -3.14159" />
      <geometry>
        <mesh filename="package://robot_description/meshes/link_4_visual.stl" />
      </geometry>
      <material name="link_4_parts_material">
        <color rgba="0.5 0.5 0.5 1" />
      </material>
    </visual>
    <collision>
      <origin xyz="1.65309e-07 0.0356415 -0.0384232" rpy="1.5708 -2.40282e-15 -3.14159" />
      <geometry>
        <mesh filename="package://robot_description/meshes/link_4_collision.stl" />
      </geometry>
    </collision>
  </link>
  
  <link name="link_5">
    <inertial>
      <origin xyz="2.88362e-05 0.00116186 0.0681861" rpy="0 0 0" />
      <mass value="0.367859" />
      <inertia ixx="0.000951525" ixy="-6.17371e-07" ixz="7.15616e-07" iyy="0.000703296" iyz="-1.58191e-05" izz="0.000545148" />
    </inertial>
    
    <visual>
      <origin xyz="2.88362e-05 0.00116186 0.0681861" rpy="2.76412e-15 1.30658e-15 -3.14159" />
      <geometry>
        <mesh filename="package://robot_description/meshes/link_5_visual.stl" />
      </geometry>
      <material name="link_5_parts_material">
        <color rgba="0.5 0.5 0.5 1" />
      </material>
    </visual>
    <collision>
      <origin xyz="2.88362e-05 0.00116186 0.0681861" rpy="2.76412e-15 1.30658e-15 -3.14159" />
      <geometry>
        <mesh filename="package://robot_description/meshes/link_5_collision.stl" />
      </geometry>
    </collision>
  </link>
  
  <link name="link_6">
    <inertial>
      <origin xyz="-0.00199257 -4.2631e-08 1.04217e-05" rpy="0 0 0" />
      <mass value="0.164337" />
      <inertia ixx="0.000142335" ixy="5.40234e-11" ixz="-3.39857e-09" iyy="0.000139708" iyz="1.23811e-07" izz="3.04379e-05" />
    </inertial>
    
    <visual>
      <origin xyz="-0.00199257 -4.2631e-08 1.04217e-05" rpy="1.5708 9.15934e-15 -1.5708" />
      <geometry>
        <mesh filename="package://robot_description/meshes/link_6_visual.stl" />
      </geometry>
      <material name="link_6_parts_material">
        <color rgba="0.5 0.5 0.5 1" />
      </material>
    </visual>
    <collision>
      <origin xyz="-0.00199257 -4.2631e-08 1.04217e-05" rpy="1.5708 9.15934e-15 -1.5708" />
      <geometry>
        <mesh filename="package://robot_description/meshes/link_6_collision.stl" />
      </geometry>
    </collision>
  </link>
  
  <link name="link_7">
    <inertial>
      <origin xyz="-0.000507071 0.000598017 0.0311633" rpy="0 0 0" />
      <mass value="0.117107" />
      <inertia ixx="5.16881e-05" ixy="-2.22858e-07" ixz="-8.23951e-07" iyy="5.43034e-05" iyz="-1.9419e-07" izz="5.19564e-05" />
    </inertial>
    
    <visual>
      <origin xyz="-0.000507071 0.000598017 0.0311633" rpy="7.07579e-15 1.30658e-15 -1.5708" />
      <geometry>
        <mesh filename="package://robot_description/meshes/link_7_visual.stl" />
      </geometry>
      <material name="link_7_parts_material">
        <color rgba="0.5 0.5 0.5 1" />
      </material>
    </visual>
    <collision>
      <origin xyz="-0.000507071 0.000598017 0.0311633" rpy="7.07579e-15 1.30658e-15 -1.5708" />
      <geometry>
        <mesh filename="package://robot_description/meshes/link_7_collision.stl" />
      </geometry>
    </collision>
  </link>
  
  <link name="tool_changer">
    <origin xyz="0 0 0" rpy="0 -0 0" />
    <inertial>
      <origin xyz="0 0 0" rpy="0 0 0" />
      <mass value="1e-9" />
      <inertia ixx="0" ixy="0" ixz="0" iyy="0" iyz="0" izz="0" />
    </inertial>
  </link>
  <joint name="tool_changer_frame" type="fixed">
    <origin xyz="-6.41848e-17 8.44637e-18 0.047085" rpy="1.99408e-15 -9.35725e-16 -1.5708" />
    <parent link="link_7" />
    <child link="tool_changer" />
    <axis xyz="0 0 0" />
  </joint>
  
  <link name="gripper_tcp">
    <origin xyz="0 0 0" rpy="0 -0 0" />
    <inertial>
      <origin xyz="0 0 0" rpy="0 0 0" />
      <mass value="1e-9" />
      <inertia ixx="0" ixy="0" ixz="0" iyy="0" iyz="0" izz="0" />
    </inertial>
  </link>
  <joint name="gripper_tcp_frame" type="fixed">
    <origin xyz="-2.15106e-16 2.25417e-16 0.106885" rpy="2.58091e-15 -6.24476e-15 -1.5708" />
    <parent link="link_7" />
    <child link="gripper_tcp" />
    <axis xyz="0 0 0" />
  </joint>
  
  <joint name="joint_6" type="revolute">
    <origin xyz="-0.0110489 4.69647e-18 -1.9082e-17" rpy="-3.24826e-16 -1.5708 0" />
    <parent link="link_6" />
    <child link="link_7" />
    <axis xyz="0 0 1" />
    <limit effort="10" velocity="10" lower="-3.14159" upper="3.14159" />
  </joint>
  
  <joint name="joint_5" type="revolute">
    <origin xyz="-4.66156e-17 3.1225e-17 0.1125" rpy="1.5708 1.5708 0" />
    <parent link="link_5" />
    <child link="link_6" />
    <axis xyz="0 0 1" />
    <limit effort="10" velocity="10" lower="-1.5708" upper="1.5708" />
  </joint>
  
  <joint name="joint_4" type="revolute">
    <origin xyz="-1.9521e-17 0.076 -0.05" rpy="-1.5708 1.11022e-16 -1.11022e-16" />
    <parent link="link_4" />
    <child link="link_5" />
    <axis xyz="0 0 1" />
    <limit effort="10" velocity="10" lower="-3.14159" upper="3.14159" />
  </joint>
  
  <joint name="joint_3" type="revolute">
    <origin xyz="4.2689e-08 0.2 -0.0259997" rpy="-5.69636e-17 -4.65589e-15 -1.33291e-15" />
    <parent link="link_3" />
    <child link="link_4" />
    <axis xyz="0 0 1" />
    <limit effort="10" velocity="10" lower="-3.14159" upper="3.14159" />
  </joint>
  
  <joint name="joint_2" type="revolute">
    <origin xyz="1.17358e-16 -0.0895 0.0575" rpy="1.5708 -1.3735e-16 2.25307e-15" />
    <parent link="link_2" />
    <child link="link_3" />
    <axis xyz="0 0 1" />
    <limit effort="10" velocity="10" lower="-3.14159" upper="3.14159" />
  </joint>
  
  <joint name="joint_1" type="revolute">
    <origin xyz="-9.71219e-17 7.33525e-17 0.1245" rpy="0 -0 3.14159" />
    <parent link="link_1" />
    <child link="link_2" />
    <axis xyz="0 0 1" />
    <limit effort="10" velocity="10" lower="-3.14159" upper="3.14159" />
  </joint>
  
  <joint name="base_link_to_link_1" type="fixed">
    <origin xyz="0 0 0" rpy="0 -0 0" />
    <parent link="base_link" />
    <child link="link_1" />
    <axis xyz="0 0 1" />
    <limit effort="10" velocity="10" />
  </joint>
  
  <ros2_control name="robot" type="system">
    <hardware>
      <plugin>robot_hardware/RobotSystem</plugin>
    </hardware>
    <joint name="joint_1">
      <command_interface name="position">
        <param name="min">${-2*pi}</param>
        <param name="max">${2*pi}</param>
      </command_interface>
      <command_interface name="velocity">
        <param name="min">-3.15</param>
        <param name="max">3.15</param>
      </command_interface>
      <state_interface name="position">
        <param name="initial_value">0.0</param>
      </state_interface>
      <state_interface name="velocity" />
    </joint>
    <joint name="joint_2">
      <command_interface name="position">
        <param name="min">${-2*pi}</param>
        <param name="max">${2*pi}</param>
      </command_interface>
      <command_interface name="velocity">
        <param name="min">-3.15</param>
        <param name="max">3.15</param>
      </command_interface>
      <state_interface name="position">
        <param name="initial_value">0.0</param>
      </state_interface>
      <state_interface name="velocity" />
    </joint>
    <joint name="joint_3">
      <command_interface name="position">
        <param name="min">${-pi}</param>
        <param name="max">${pi}</param>
      </command_interface>
      <command_interface name="velocity">
        <param name="min">-3.15</param>
        <param name="max">3.15</param>
      </command_interface>
      <state_interface name="position">
        <param name="initial_value">0.0</param>
      </state_interface>
      <state_interface name="velocity" />
    </joint>
    <joint name="joint_4">
      <command_interface name="position">
        <param name="min">${-2*pi}</param>
        <param name="max">${2*pi}</param>
      </command_interface>
      <command_interface name="velocity">
        <param name="min">-3.2</param>
        <param name="max">3.2</param>
      </command_interface>
      <state_interface name="position">
        <param name="initial_value">0.0</param>
      </state_interface>
      <state_interface name="velocity" />
    </joint>
    <joint name="joint_5">
      <command_interface name="position">
        <param name="min">${-2*pi}</param>
        <param name="max">${2*pi}</param>
      </command_interface>
      <command_interface name="velocity">
        <param name="min">-3.2</param>
        <param name="max">3.2</param>
      </command_interface>
      <state_interface name="position">
        <param name="initial_value">0.0</param>
      </state_interface>
      <state_interface name="velocity" />
    </joint>
    <joint name="joint_6">
      <command_interface name="position">
        <param name="min">${-2*pi}</param>
        <param name="max">${2*pi}</param>
      </command_interface>
      <command_interface name="velocity">
        <param name="min">-3.2</param>
        <param name="max">3.2</param>
      </command_interface>
      <state_interface name="position">
        <param name="initial_value">0.0</param>
      </state_interface>
      <state_interface name="velocity" />
    </joint>
    <sensor name="tcp_fts_sensor">
      <state_interface name="force.x" />
      <state_interface name="force.y" />
      <state_interface name="force.z" />
      <state_interface name="torque.x" />
      <state_interface name="torque.y" />
      <state_interface name="torque.z" />
    </sensor>
  </ros2_control>
</robot>