<robot name="robot">
  
  <link name="base_link" />
<link name="link_1">
    <inertial>
      <origin xyz="2.77696e-08 -7.61703e-05 0.0796192" rpy="0 0 0" />
      <mass value="0.762917" />
      <inertia ixx="0.00155042" ixy="-1.03652e-07" ixz="3.59686e-07" iyy="0.00155346" iyz="3.0939e-07" izz="0.00110981" />
    </inertial>
    
    <visual>
      <origin xyz="2.77696e-08 -7.61703e-05 0.0796192" rpy="0 -0 0" />
      <geometry>
        <mesh filename="package://robot_description/meshes/link_1_visual.stl" />
      </geometry>
      <material name="link_1_parts_material">
        <color rgba="0.5 0.5 0.5 1" />
      </material>
    </visual>
    <collision>
      <origin xyz="2.77696e-08 -7.61703e-05 0.0796192" rpy="0 -0 0" />
      <geometry>
        <mesh filename="package://robot_description/meshes/link_1_collision.stl" />
      </geometry>
    </collision>
  </link>
  
  <link name="world">
    <origin xyz="0 0 0" rpy="0 -0 0" />
    <inertial>
      <origin xyz="0 0 0" rpy="0 0 0" />
      <mass value="1e-9" />
      <inertia ixx="0" ixy="0" ixz="0" iyy="0" iyz="0" izz="0" />
    </inertial>
  </link>
  <joint name="world_frame" type="fixed">
    <origin xyz="2.17302e-29 -0.35 9.48385e-76" rpy="-2.70967e-75 -8.73725e-47 -6.20864e-29" />
    <parent link="link_1" />
    <child link="world" />
    <axis xyz="0 0 0" />
  </joint>
  
  <link name="link_2">
    <inertial>
      <origin xyz="-0.0537127 8.70142e-08 0.0492254" rpy="0 0 0" />
      <mass value="0.632802" />
      <inertia ixx="0.000845867" ixy="-6.13943e-09" ixz="0.000284499" iyy="0.00107039" iyz="4.65187e-09" izz="0.00100812" />
    </inertial>
    
    <visual>
      <origin xyz="-0.0537127 8.70142e-08 0.0492254" rpy="4.25856e-61 -6.85909e-33 -1.5708" />
      <geometry>
        <mesh filename="package://robot_description/meshes/link_2_visual.stl" />
      </geometry>
      <material name="link_2_parts_material">
        <color rgba="0.5 0.5 0.5 1" />
      </material>
    </visual>
    <collision>
      <origin xyz="-0.0537127 8.70142e-08 0.0492254" rpy="4.25856e-61 -6.85909e-33 -1.5708" />
      <geometry>
        <mesh filename="package://robot_description/meshes/link_2_collision.stl" />
      </geometry>
    </collision>
  </link>
  
  <link name="link_3">
    <inertial>
      <origin xyz="-0.13001 -1.22089e-07 0.0184672" rpy="0 0 0" />
      <mass value="0.701897" />
      <inertia ixx="0.0010184" ixy="7.19768e-09" ixz="-0.000683364" iyy="0.00525569" iyz="-3.69861e-07" izz="0.00499575" />
    </inertial>
    
    <visual>
      <origin xyz="-0.13001 -1.22089e-07 0.0184672" rpy="-1.5708 -1.21569e-14 1.5708" />
      <geometry>
        <mesh filename="package://robot_description/meshes/link_3_visual.stl" />
      </geometry>
      <material name="link_3_parts_material">
        <color rgba="0.5 0.5 0.5 1" />
      </material>
    </visual>
    <collision>
      <origin xyz="-0.13001 -1.22089e-07 0.0184672" rpy="-1.5708 -1.21569e-14 1.5708" />
      <geometry>
        <mesh filename="package://robot_description/meshes/link_3_collision.stl" />
      </geometry>
    </collision>
  </link>
  
  <link name="link_4">
    <inertial>
      <origin xyz="1.5685e-08 0.0432072 -0.0420781" rpy="0 0 0" />
      <mass value="0.414434" />
      <inertia ixx="0.000514794" ixy="-3.72268e-07" ixz="3.99492e-10" iyy="0.000385737" iyz="0.000143609" izz="0.000474449" />
    </inertial>
    
    <visual>
      <origin xyz="1.5685e-08 0.0432072 -0.0420781" rpy="-1.5708 -1.05301e-16 2.25321e-16" />
      <geometry>
        <mesh filename="package://robot_description/meshes/link_4_visual.stl" />
      </geometry>
      <material name="link_4_parts_material">
        <color rgba="0.5 0.5 0.5 1" />
      </material>
    </visual>
    <collision>
      <origin xyz="1.5685e-08 0.0432072 -0.0420781" rpy="-1.5708 -1.05301e-16 2.25321e-16" />
      <geometry>
        <mesh filename="package://robot_description/meshes/link_4_collision.stl" />
      </geometry>
    </collision>
  </link>
  
  <link name="link_5">
    <inertial>
      <origin xyz="-0.00142765 2.82885e-05 0.068926" rpy="0 0 0" />
      <mass value="0.382902" />
      <inertia ixx="0.000740932" ixy="9.75429e-07" ixz="2.11116e-05" iyy="0.00104134" iyz="8.17041e-07" izz="0.000616513" />
    </inertial>
    
    <visual>
      <origin xyz="-0.00142765 2.82885e-05 0.068926" rpy="-2.60381e-15 1.77308e-15 1.5708" />
      <geometry>
        <mesh filename="package://robot_description/meshes/link_5_visual.stl" />
      </geometry>
      <material name="link_5_parts_material">
        <color rgba="0.5 0.5 0.5 1" />
      </material>
    </visual>
    <collision>
      <origin xyz="-0.00142765 2.82885e-05 0.068926" rpy="-2.60381e-15 1.77308e-15 1.5708" />
      <geometry>
        <mesh filename="package://robot_description/meshes/link_5_collision.stl" />
      </geometry>
    </collision>
  </link>
  
  <link name="link_6">
    <inertial>
      <origin xyz="-0.00168121 -3.01195e-05 1.05506e-05" rpy="0 0 0" />
      <mass value="0.180127" />
      <inertia ixx="0.000175076" ixy="2.54386e-08" ixz="-3.49791e-09" iyy="0.00017259" iyz="-4.74944e-08" izz="3.43052e-05" />
    </inertial>
    
    <visual>
      <origin xyz="-0.00168121 -3.01195e-05 1.05506e-05" rpy="-1.5708 -1.1045e-15 1.5708" />
      <geometry>
        <mesh filename="package://robot_description/meshes/link_6_visual.stl" />
      </geometry>
      <material name="link_6_parts_material">
        <color rgba="0.5 0.5 0.5 1" />
      </material>
    </visual>
    <collision>
      <origin xyz="-0.00168121 -3.01195e-05 1.05506e-05" rpy="-1.5708 -1.1045e-15 1.5708" />
      <geometry>
        <mesh filename="package://robot_description/meshes/link_6_collision.stl" />
      </geometry>
    </collision>
  </link>
  
  <link name="link_7">
    <inertial>
      <origin xyz="-0.000491381 0.000661972 0.0271796" rpy="0 0 0" />
      <mass value="0.109068" />
      <inertia ixx="3.15055e-05" ixy="-1.61806e-07" ixz="-5.37791e-07" iyy="3.26065e-05" iyz="6.63679e-08" izz="3.62559e-05" />
    </inertial>
    
    <visual>
      <origin xyz="-0.000491381 0.000661972 0.0271796" rpy="-7.04986e-16 -5.87872e-17 1.5708" />
      <geometry>
        <mesh filename="package://robot_description/meshes/link_7_visual.stl" />
      </geometry>
      <material name="link_7_parts_material">
        <color rgba="0.5 0.5 0.5 1" />
      </material>
    </visual>
    <collision>
      <origin xyz="-0.000491381 0.000661972 0.0271796" rpy="-7.04986e-16 -5.87872e-17 1.5708" />
      <geometry>
        <mesh filename="package://robot_description/meshes/link_7_collision.stl" />
      </geometry>
    </collision>
  </link>
  
  <joint name="joint_6" type="revolute">
    <origin xyz="-0.0110489 3.75536e-16 -2.55004e-16" rpy="-9.99201e-16 -1.5708 0" />
    <parent link="link_6" />
    <child link="link_7" />
    <axis xyz="0 0 1" />
    <limit effort="10" velocity="10" lower="-3.14159" upper="3.14159" />
  </joint>
  
  <joint name="joint_5" type="revolute">
    <origin xyz="1.73472e-18 6.57331e-18 0.1125" rpy="9.99201e-16 1.5708 0" />
    <parent link="link_5" />
    <child link="link_6" />
    <axis xyz="0 0 1" />
    <limit effort="10" velocity="10" lower="-1.5708" upper="1.5708" />
  </joint>
  
  <joint name="joint_4" type="revolute">
    <origin xyz="-3.86347e-16 0.076 -0.05" rpy="-1.5708 -1.5708 0" />
    <parent link="link_4" />
    <child link="link_5" />
    <axis xyz="0 0 1" />
    <limit effort="10" velocity="10" lower="-3.14159" upper="3.14159" />
  </joint>
  
  <joint name="joint_3" type="revolute">
    <origin xyz="-0.2 4.2689e-08 -0.0259997" rpy="-7.21645e-15 -1.20516e-14 1.5708" />
    <parent link="link_3" />
    <child link="link_4" />
    <axis xyz="0 0 1" />
    <limit effort="10" velocity="10" lower="-3.14159" upper="3.14159" />
  </joint>
  
  <joint name="joint_2" type="revolute">
    <origin xyz="-0.0895 -1.04373e-16 0.0575" rpy="3.14159 1.5708 0" />
    <parent link="link_2" />
    <child link="link_3" />
    <axis xyz="0 0 1" />
    <limit effort="10" velocity="10" lower="-3.14159" upper="3.14159" />
  </joint>
  
  <joint name="joint_1" type="revolute">
    <origin xyz="-9.10289e-17 2.10067e-17 0.1245" rpy="6.85909e-33 -0 1.5708" />
    <parent link="link_1" />
    <child link="link_2" />
    <axis xyz="0 0 1" />
    <limit effort="10" velocity="10" lower="-3.14159" upper="3.14159" />
  </joint>
  
  <joint name="base_link_to_link_1" type="fixed">
    <origin xyz="0 0 0" rpy="0 -0 0" />
    <parent link="base_link" />
    <child link="link_1" />
    <axis xyz="0 0 1" />
    <limit effort="10" velocity="10" />
  </joint>
  
  <ros2_control name="robot" type="system">
    <hardware>
      <plugin>robot_hardware/RobotSystem</plugin>
    </hardware>
    <joint name="joint_1">
      <command_interface name="position">
        <param name="min">${-2*pi}</param>
        <param name="max">${2*pi}</param>
      </command_interface>
      <command_interface name="velocity">
        <param name="min">-3.15</param>
        <param name="max">3.15</param>
      </command_interface>
      <state_interface name="position">
        <param name="initial_value">0.0</param>
      </state_interface>
      <state_interface name="velocity" />
    </joint>
    <joint name="joint_2">
      <command_interface name="position">
        <param name="min">${-2*pi}</param>
        <param name="max">${2*pi}</param>
      </command_interface>
      <command_interface name="velocity">
        <param name="min">-3.15</param>
        <param name="max">3.15</param>
      </command_interface>
      <state_interface name="position">
        <param name="initial_value">0.0</param>
      </state_interface>
      <state_interface name="velocity" />
    </joint>
    <joint name="joint_3">
      <command_interface name="position">
        <param name="min">${-pi}</param>
        <param name="max">${pi}</param>
      </command_interface>
      <command_interface name="velocity">
        <param name="min">-3.15</param>
        <param name="max">3.15</param>
      </command_interface>
      <state_interface name="position">
        <param name="initial_value">0.0</param>
      </state_interface>
      <state_interface name="velocity" />
    </joint>
    <joint name="joint_4">
      <command_interface name="position">
        <param name="min">${-2*pi}</param>
        <param name="max">${2*pi}</param>
      </command_interface>
      <command_interface name="velocity">
        <param name="min">-3.2</param>
        <param name="max">3.2</param>
      </command_interface>
      <state_interface name="position">
        <param name="initial_value">0.0</param>
      </state_interface>
      <state_interface name="velocity" />
    </joint>
    <joint name="joint_5">
      <command_interface name="position">
        <param name="min">${-2*pi}</param>
        <param name="max">${2*pi}</param>
      </command_interface>
      <command_interface name="velocity">
        <param name="min">-3.2</param>
        <param name="max">3.2</param>
      </command_interface>
      <state_interface name="position">
        <param name="initial_value">0.0</param>
      </state_interface>
      <state_interface name="velocity" />
    </joint>
    <joint name="joint_6">
      <command_interface name="position">
        <param name="min">${-2*pi}</param>
        <param name="max">${2*pi}</param>
      </command_interface>
      <command_interface name="velocity">
        <param name="min">-3.2</param>
        <param name="max">3.2</param>
      </command_interface>
      <state_interface name="position">
        <param name="initial_value">0.0</param>
      </state_interface>
      <state_interface name="velocity" />
    </joint>
    <sensor name="tcp_fts_sensor">
      <state_interface name="force.x" />
      <state_interface name="force.y" />
      <state_interface name="force.z" />
      <state_interface name="torque.x" />
      <state_interface name="torque.y" />
      <state_interface name="torque.z" />
    </sensor>
  </ros2_control>
</robot>