<robot name="r6bot">
  
  <link name="link_1">
    <inertial>
      <origin xyz="1.56892e-07 -0.000137144 0.0615947" rpy="0 0 0" />
      <mass value="0.461414" />
      <inertia ixx="0.00101733" ixy="1.92325e-08" ixz="3.05816e-09" iyy="0.00102046" iyz="-3.57275e-06" izz="0.000880071" />
    </inertial>
    
    <visual>
      <origin xyz="1.56892e-07 -0.000137144 0.0615947" rpy="0 -0 0" />
      <geometry>
        <mesh filename="package://meshes/link_1_visual.stl" />
      </geometry>
      <material name="link_1_parts_material">
        <color rgba="0.5 0.5 0.5 1" />
      </material>
    </visual>
    <collision>
      <origin xyz="1.56892e-07 -0.000137144 0.0615947" rpy="0 -0 0" />
      <geometry>
        <mesh filename="package://meshes/link_1_collision.stl" />
      </geometry>
    </collision>
  </link>
  
  <link name="link_2">
    <inertial>
      <origin xyz="-6.10023e-07 -0.0383285 -0.043327" rpy="0 0 0" />
      <mass value="0.331666" />
      <inertia ixx="0.000658747" ixy="-1.99208e-09" ixz="-3.80044e-09" iyy="0.000569808" iyz="-0.000179151" izz="0.000643797" />
    </inertial>
    
    <visual>
      <origin xyz="-6.10023e-07 -0.0383285 -0.043327" rpy="3.14159 2.21112e-32 3.14159" />
      <geometry>
        <mesh filename="package://meshes/link_2_visual.stl" />
      </geometry>
      <material name="link_2_parts_material">
        <color rgba="0.5 0.5 0.5 1" />
      </material>
    </visual>
    <collision>
      <origin xyz="-6.10023e-07 -0.0383285 -0.043327" rpy="3.14159 2.21112e-32 3.14159" />
      <geometry>
        <mesh filename="package://meshes/link_2_collision.stl" />
      </geometry>
    </collision>
  </link>
  
  <link name="link_3">
    <inertial>
      <origin xyz="-0.0748564 0.0766746 -0.028902" rpy="0 0 0" />
      <mass value="0.498148" />
      <inertia ixx="0.00219799" ixy="0.00143809" ixz="0.000137066" iyy="0.00212889" iyz="-0.000140407" izz="0.00352706" />
    </inertial>
    
    <visual>
      <origin xyz="-0.0748564 0.0766746 -0.028902" rpy="1.5708 -1.94096e-14 3.14159" />
      <geometry>
        <mesh filename="package://meshes/link_3_visual.stl" />
      </geometry>
      <material name="link_3_parts_material">
        <color rgba="0.5 0.5 0.5 1" />
      </material>
    </visual>
    <collision>
      <origin xyz="-0.0748564 0.0766746 -0.028902" rpy="1.5708 -1.94096e-14 3.14159" />
      <geometry>
        <mesh filename="package://meshes/link_3_collision.stl" />
      </geometry>
    </collision>
  </link>
  
  <link name="link_4">
    <inertial>
      <origin xyz="-1.79188e-07 -0.0306184 -0.0370489" rpy="0 0 0" />
      <mass value="0.216205" />
      <inertia ixx="0.000309924" ixy="8.38519e-10" ixz="8.78549e-11" iyy="0.000260935" iyz="-8.53983e-05" izz="0.000298819" />
    </inertial>
    
    <visual>
      <origin xyz="-1.79188e-07 -0.0306184 -0.0370489" rpy="-1.5708 1.94243e-14 2.30911" />
      <geometry>
        <mesh filename="package://meshes/link_4_visual.stl" />
      </geometry>
      <material name="link_4_parts_material">
        <color rgba="0.5 0.5 0.5 1" />
      </material>
    </visual>
    <collision>
      <origin xyz="-1.79188e-07 -0.0306184 -0.0370489" rpy="-1.5708 1.94243e-14 2.30911" />
      <geometry>
        <mesh filename="package://meshes/link_4_collision.stl" />
      </geometry>
    </collision>
  </link>
  
  <link name="link_5">
    <inertial>
      <origin xyz="-1.82907e-07 -0.00076381 -0.0682148" rpy="0 0 0" />
      <mass value="0.363068" />
      <inertia ixx="0.000946632" ixy="-1.62957e-08" ixz="1.0587e-07" iyy="0.000705783" iyz="-1.24047e-05" izz="0.000535574" />
    </inertial>
    
    <visual>
      <origin xyz="-1.82907e-07 -0.00076381 -0.0682148" rpy="-3.14159 -0.832485 3.14159" />
      <geometry>
        <mesh filename="package://meshes/link_5_visual.stl" />
      </geometry>
      <material name="link_5_parts_material">
        <color rgba="0.5 0.5 0.5 1" />
      </material>
    </visual>
    <collision>
      <origin xyz="-1.82907e-07 -0.00076381 -0.0682148" rpy="-3.14159 -0.832485 3.14159" />
      <geometry>
        <mesh filename="package://meshes/link_5_collision.stl" />
      </geometry>
    </collision>
  </link>
  
  <link name="link_6">
    <inertial>
      <origin xyz="0.00218112 0.000356863 1.16162e-05" rpy="0 0 0" />
      <mass value="0.15061" />
      <inertia ixx="0.000123959" ixy="4.22653e-07" ixz="2.37806e-08" iyy="0.000121445" iyz="-1.21561e-07" izz="2.97575e-05" />
    </inertial>
    
    <visual>
      <origin xyz="0.00218112 0.000356863 1.16162e-05" rpy="1.5708 3.87166e-15 -2.30911" />
      <geometry>
        <mesh filename="package://meshes/link_6_visual.stl" />
      </geometry>
      <material name="link_6_parts_material">
        <color rgba="0.5 0.5 0.5 1" />
      </material>
    </visual>
    <collision>
      <origin xyz="0.00218112 0.000356863 1.16162e-05" rpy="1.5708 3.87166e-15 -2.30911" />
      <geometry>
        <mesh filename="package://meshes/link_6_collision.stl" />
      </geometry>
    </collision>
  </link>
  
  <link name="link_7">
    <inertial>
      <origin xyz="-0.000274308 -0.000815168 -0.0322826" rpy="0 0 0" />
      <mass value="0.171084" />
      <inertia ixx="9.39426e-05" ixy="2.95457e-07" ixz="1.07276e-08" iyy="9.66511e-05" iyz="-7.96874e-07" izz="8.00941e-05" />
    </inertial>
    
    <visual>
      <origin xyz="-0.000274308 -0.000815168 -0.0322826" rpy="1.60365e-13 -0.900467 1.5708" />
      <geometry>
        <mesh filename="package://meshes/link_7_visual.stl" />
      </geometry>
      <material name="link_7_parts_material">
        <color rgba="0.5 0.5 0.5 1" />
      </material>
    </visual>
    <collision>
      <origin xyz="-0.000274308 -0.000815168 -0.0322826" rpy="1.60365e-13 -0.900467 1.5708" />
      <geometry>
        <mesh filename="package://meshes/link_7_collision.stl" />
      </geometry>
    </collision>
  </link>
  
  <joint name="joint_6" type="revolute">
    <origin xyz="0.0109039 0.0017838 4.27956e-15" rpy="2.97944 1.5708 0" />
    <parent link="link_6" />
    <child link="link_7" />
    <axis xyz="0 0 1" />
    <limit effort="10" velocity="10" lower="-6.28319" upper="0" />
  </joint>
  
  <joint name="joint_5" type="revolute">
    <origin xyz="-5.55112e-17 1.73472e-18 -0.1125" rpy="-1.5708 -1.84512e-15 -3.11039e-14" />
    <parent link="link_5" />
    <child link="link_6" />
    <axis xyz="0 0 1" />
    <limit effort="10" velocity="10" lower="-0.162156" upper="2.97944" />
  </joint>
  
  <joint name="joint_4" type="revolute">
    <origin xyz="-1.11022e-16 -0.076 -0.05" rpy="-1.5708 -6.48265e-16 -1.8837e-16" />
    <parent link="link_4" />
    <child link="link_5" />
    <axis xyz="0 0 1" />
    <limit effort="10" velocity="10" lower="-3.10862e-14" upper="6.28319" />
  </joint>
  
  <joint name="joint_3" type="revolute">
    <origin xyz="-0.139714 0.143108 0.0259997" rpy="-3.14159 2.36039e-15 -0.832485" />
    <parent link="link_3" />
    <child link="link_4" />
    <axis xyz="0 0 1" />
    <limit effort="10" velocity="10" lower="-4.74747" upper="1.53571" />
  </joint>
  
  <joint name="joint_2" type="revolute">
    <origin xyz="1.83707e-15 -0.0895 -0.0575" rpy="-1.5708 2.22045e-16 1.94096e-14" />
    <parent link="link_2" />
    <child link="link_3" />
    <axis xyz="0 0 1" />
    <limit effort="10" velocity="10" lower="-3.91499" upper="2.3682" />
  </joint>
  
  <joint name="joint_1" type="revolute">
    <origin xyz="-6.00804e-17 5.03629e-17 0.1245" rpy="3.14159 -2.21112e-32 3.14159" />
    <parent link="link_1" />
    <child link="link_2" />
    <axis xyz="0 0 1" />
    <limit effort="10" velocity="10" lower="0" upper="6.28319" />
  </joint>
  
  <joint name="base_link_to_link_1" type="fixed">
    <origin xyz="0 0 0" rpy="0 -0 0" />
    <parent link="base_link" />
    <child link="link_1" />
    <axis xyz="0 0 1" />
    <limit effort="10" velocity="10" />
  </joint>
  
  <ros2_control name="r6bot" type="system">
    <hardware>
      <plugin>r6bot_hardware/RobotSystem</plugin>
    </hardware>
    <joint name="joint_1">
      <command_interface name="position">
        <param name="min">${-2*pi}</param>
        <param name="max">${2*pi}</param>
      </command_interface>
      <command_interface name="velocity">
        <param name="min">-3.15</param>
        <param name="max">3.15</param>
      </command_interface>
      <state_interface name="position">
        <param name="initial_value">0.0</param>
      </state_interface>
      <state_interface name="velocity" />
    </joint>
    <joint name="joint_2">
      <command_interface name="position">
        <param name="min">${-2*pi}</param>
        <param name="max">${2*pi}</param>
      </command_interface>
      <command_interface name="velocity">
        <param name="min">-3.15</param>
        <param name="max">3.15</param>
      </command_interface>
      <state_interface name="position">
        <param name="initial_value">0.0</param>
      </state_interface>
      <state_interface name="velocity" />
    </joint>
    <joint name="joint_3">
      <command_interface name="position">
        <param name="min">${-pi}</param>
        <param name="max">${pi}</param>
      </command_interface>
      <command_interface name="velocity">
        <param name="min">-3.15</param>
        <param name="max">3.15</param>
      </command_interface>
      <state_interface name="position">
        <param name="initial_value">0.0</param>
      </state_interface>
      <state_interface name="velocity" />
    </joint>
    <joint name="joint_4">
      <command_interface name="position">
        <param name="min">${-2*pi}</param>
        <param name="max">${2*pi}</param>
      </command_interface>
      <command_interface name="velocity">
        <param name="min">-3.2</param>
        <param name="max">3.2</param>
      </command_interface>
      <state_interface name="position">
        <param name="initial_value">0.0</param>
      </state_interface>
      <state_interface name="velocity" />
    </joint>
    <joint name="joint_5">
      <command_interface name="position">
        <param name="min">${-2*pi}</param>
        <param name="max">${2*pi}</param>
      </command_interface>
      <command_interface name="velocity">
        <param name="min">-3.2</param>
        <param name="max">3.2</param>
      </command_interface>
      <state_interface name="position">
        <param name="initial_value">0.0</param>
      </state_interface>
      <state_interface name="velocity" />
    </joint>
    <joint name="joint_6">
      <command_interface name="position">
        <param name="min">${-2*pi}</param>
        <param name="max">${2*pi}</param>
      </command_interface>
      <command_interface name="velocity">
        <param name="min">-3.2</param>
        <param name="max">3.2</param>
      </command_interface>
      <state_interface name="position">
        <param name="initial_value">0.0</param>
      </state_interface>
      <state_interface name="velocity" />
    </joint>
    <sensor name="tcp_fts_sensor">
      <state_interface name="force.x" />
      <state_interface name="force.y" />
      <state_interface name="force.z" />
      <state_interface name="torque.x" />
      <state_interface name="torque.y" />
      <state_interface name="torque.z" />
    </sensor>
  </ros2_control>
<link name="base_link" /></robot>